Workbook
Name Deal_Type: [1]Inputs!$H$12
Name IRR: [1]Inputs!$F$45
Name IRR_wo: [1]Inputs!$G$45
Name Org_Struct: [1]Inputs!$H$11
Name print_all: 'Pro Forma Financials'!print_all
Name print_all: [0]!print_all
Name Project_Name: [1]Inputs!$H$9
Name Strat: [1]Inputs!$H$10
Name Target: [1]Inputs!$H$8
Name Tax_rate: [1]Inputs!$H$60
Name TTM_Date: [1]Inputs!$H$13
Name WACC: [1]Inputs!$H$73

Sheet Project Rocky
A5: Project Rocky
A7: Finance & Operations Diligence

Sheet Top Client Accounts
A1: Project Rocky
A2: Top Client Accounts
B4: Client | C4: Premium | D4: Commissions | E4: % of Total | F4: Commentary
A5: 1 | B5: Chandler Trust | C5: 606033.06 | D5: 75754.133 | E5: =D5/$D$128 -> 0.1704834
A6: 2 | B6: Pisces Inc. | C6: 309863 | D6: 38732.875 | E6: =D6/$D$128 -> 0.087167684
A7: 3 | B7: Westerman Family Office | C7: 219003 | D7: 26877.1 | E7: =D7/$D$128 -> 0.060486461
A8: 4 | B8: Marlborough Galleries Inc & Hermes Trust Co | C8: 129085.79 | D8: 16135.724 | E8: =D8/$D$128 -> 0.036313175
A9: 5 | B9: Wind River Trust Company | C9: 93073 | D9: 13745.875 | E9: =D9/$D$128 -> 0.03093486
A10: 6 | B10: Lorenz | C10: 108029 | D10: 13477.005 | E10: =D10/$D$128 -> 0.030329773
A11: 7 | B11: Pendleton Trust Company | C11: 108524 | D11: 13442.475 | E11: =D11/$D$128 -> 0.030252064
A12: 8 | B12: EBOR (WSG(PTC)) | C12: 106777 | D12: 12813.24 | E12: =D12/$D$128 -> 0.028835981
A13: 9 | B13: TEFAF | C13: 52019 | D13: 12487.2 | E13: =D13/$D$128 -> 0.028102234
A14: 10 | B14: A7P | C14: 95578 | D14: 11947.25 | E14: =D14/$D$128 -> 0.026887085
A15: 11 | B15: Astra Management & Astra PTC | C15: 93392 | D15: 11674 | E15: =D15/$D$128 -> 0.026272141
A16: 12 | B16: Madsen Assets | C16: 88594 | D16: 11074.25 | E16: =D16/$D$128 -> 0.024922413
... A24: 20 | B24: Investors Preferred | C24: 52673.66 | D24: 6142.9309 | E24: =D24/$D$128 -> 0.013824563
A25: 21 | B25: Saul Costa | D25: 5000 | E25: =D25/$D$128 -> 0.011252416
A26: 22 | B26: Steven A. Braun | C26: 38057 | D26: 4757.135 | E26: =D26/$D$128 -> 0.010705852
A27: 23 | B27: Baysore & Christian | C27: 44677 | D27: 4740.71 | E27: =D27/$D$128 -> 0.010668888
A28: 24 | B28: Fortius Metals Inc | C28: 47379.57 | D28: 4737.957 | E28: =D28/$D$128 -> 0.010662693
A29: 25 | B29: Center of the Golden One | C29: 13295 | D29: 4661.875 | E29: =D29/$D$128 -> 0.010491471
A30: 26 | B30: Herman Smith | C30: 36200 | D30: 4525 | E30: =D30/$D$128 -> 0.010183436
A31: 27 | B31: Corvalier Trust Company (Whold Co.) | C31: 35469 | D31: 4433.625 | E31: =D31/$D$128 -> 0.0099777985
A32: 28 | B32: Loyal Trust 2 - Hunt Brothers | C32: 96034 | D32: 4393.5 | E32: =D32/$D$128 -> 0.0098874978
A33: 29 | B33: Trustee Services Group | C33: 29782 | D33: 3722.75 | E33: =D33/$D$128 -> 0.0083779862
A34: 30 | B34: Lotus Fiduciary | C34: 29665 | D34: 3677.775 | E34: =D34/$D$128 -> 0.0082767708
A35: 31 | B35: Edelweiss V LLC | C35: 28000 | D35: 3500 | E35: =D35/$D$128 -> 0.0078766911
A36: 32 | B36: Manton Foundation | C36: 26623 | D36: 3327.885 | E36: =D36/$D$128 -> 0.0074893492
A37: 33 | B37: Li-Costa Living Trust | C37: 25000 | D37: 3125 | E37: =D37/$D$128 -> 0.0070327599
... A97: 93 | B97: Center of the Golden One (Miracle of Love) | C97: 595 | D97: 74.38 | E97: =D97/$D$128 -> 0.00016739094
A98: 94 | B98: Thomas John (TJ) Schrette | C98: 3125 | E98: =D98/$D$128 -> 0
A99: 95 | B99: ATFO, LLC | C99: 13125 | E99: =D99/$D$128 -> 0
A100: 96 | B100: Atinaw, LLC | C100: 8925 | E100: =D100/$D$128 -> 0
A101: 97 | B101: Chris Utecht | C101: 7313 | E101: =D101/$D$128 -> 0
A102: 98 | B102: Dakota Hill (PTC) | C102: 20992 | E102: =D102/$D$128 -> 0
A103: 99 | B103: Dallas College Enterprise Ventures | C103: 21250 | E103: =D103/$D$128 -> 0
A104: 100 | B104: David Amar | C104: 15308 | E104: =D104/$D$128 -> 0
A105: 101 | B105: David Holland (Holland Trustees) | C105: 4078 | E105: =D105/$D$128 -> 0
A106: 102 | B106: Diana Beinart | C106: 2500 | E106: =D106/$D$128 -> 0
A107: 103 | B107: Don Parkhill | C107: 2500 | E107: =D107/$D$128 -> 0
...

Sheet Top Wholesalers
A1: Project Rocky
A2: Top Wholesalers
B4: Wholesaler | C4: Premium | D4: Commissions | E4: % of Total | F4: Commentary
A5: 1 | B5: ARC | C5: 3117457.6 | D5: 344560.69 | E5: =D5/$D$14 -> 0.77542803
A6: 2 | B6: RT & RTS | C6: 627430.96 | D6: 58780.952 | E6: =D6/$D$14 -> 0.13228554
A7: 3 | B7: Element | C7: 138290 | D7: 14317.925 | E7: =D7/$D$14 -> 0.032222249
A8: 4 | B8: Affinity | C8: 45706 | D8: 6855.9 | E8: =D8/$D$14 -> 0.015429088
A9: 5 | B9: CRC | C9: 43167.57 | D9: 4316.757 | E9: =D9/$D$14 -> 0.009714789
A10: 6 | B10: Pearl | C10: 14535 | D10: 1308.15 | E10: =D10/$D$14 -> 0.0029439696
A11: 7 | B11: ProSight | C11: 6313 | D11: 631.3 | E11: =D11/$D$14 -> 0.00142073
B12: Top Wholesalers | C12: =SUM(C5:C11) -> 3992900.1 | D12: =SUM(D5:D11) -> 430771.67 | E12: =D12/$D$14 -> 0.9694444
B13: All Other | C13: =C14-C12 -> 3849 | D13: =D14-D12 -> 13577.35 | E13: =D13/$D$14 -> 0.030555598
B14: Total | C14: ='Top Client Accounts'!C128 -> 3996749.1 | D14: ='Top Client Accounts'!D128 -> 444349.02 | E14: =D14/$D$14 -> 1

Sheet Pro Forma Financials
A1: Project Rocky
A2: Pro Forma Financials
C4: 46174 | F4: Pro Forma | H4: MMA
A5: $ in actual | B5: 2025 | C5: TTM | F5: Adjustments | H5: Pro Forma | J5: Notes to Pro forma
A6: Revenue
A7: Sales | B7: 351963.13 | C7: ='June-26 TTM '!B7-64000 -> 505203.54 | F7: =SUM('Book of Business'!H312:H316)-'Pro Forma Financials'!C8-C18 -> 86628.173 | H7: =C7+F7 -> 591831.71 | J7: MMA: Delta between Book of Business (Production Report) and P&L
A8: P&C Commissions | B8: 351963.13 | C8: =SUBTOTAL(9,C7:C7) -> 505203.54 | F8: =SUBTOTAL(9,F7:F7) -> 86628.173 | H8: =SUBTOTAL(9,H7:H7) -> 591831.71
A11: Gross Commissions & Fees | B11: 351963.13 | C11: =SUBTOTAL(9,C$7:C$9) -> 505203.54 | F11: =SUBTOTAL(9,F$7:F$9) -> 86628.173 | H11: =SUBTOTAL(9,H$7:H$9) -> 591831.71
B13: 0 | C13: =IFERROR(INDEX([1]PF_Input!$B$9:$F$89,MATCH($A13,[1]PF_Input!$B$9:$B$89,0),MATCH(C$3,[1]PF_Input!$B$5:$F$5,0)),0) -> 0 | F13: 0 | H13: =C13+F13 -> 0
A14: Sub-Broker Expense | B14: 0 | C14: =SUBTOTAL(9,C13:C13) -> 0 | F14: =SUBTOTAL(9,F13:F13) -> 0 | H14: =SUBTOTAL(9,H13:H13) -> 0
A16: Net Commissions & Fees | B16: 351963.13 | C16: =SUBTOTAL(9,C$7:C$14) -> 505203.54 | F16: =SUBTOTAL(9,F$7:F$14) -> 86628.173 | H16: =SUBTOTAL(9,H$7:H$14) -> 591831.71
A18: Beazley Contingent | B18: 64000 | C18: 64000 | H18: =C18+F18 -> 64000
A19: Contingent Income | B19: 64000 | C19: =SUBTOTAL(9,C18:C18) -> 64000 | F19: =SUBTOTAL(9,F18:F18) -> 0 | H19: =SUBTOTAL(9,H18:H18) -> 64000
A21: Premium Finance Income | B21: 0 | C21: =IFERROR(INDEX([1]PF_Input!$B$9:$F$89,MATCH($A21,[1]PF_Input!$B$9:$B$89,0),MATCH(C$3,[1]PF_Input!$B$5:$F$5,0)),0) -> 0 | F21: 0 | H21: =C21+F21 -> 0
A22: Investment Income | B22: 0 | C22: =SUBTOTAL(9,C21:C21) -> 0 | F22: =SUBTOTAL(9,F21:F21) -> 0 | H22: =SUBTOTAL(9,H21:H21) -> 0
A24: Convenience Fee Income | B24: 0 | C24: ='June-26 TTM '!B52 -> 205 | F24: 0 | H24: =C24+F24 -> 205
A25: Miscellaneous Income | B25: 0 | C25: =SUBTOTAL(9,C24:C24) -> 205 | F25: =SUBTOTAL(9,F24:F24) -> 0 | H25: =SUBTOTAL(9,H24:H24) -> 205
A27: Other Income | B27: 64000 | C27: =SUBTOTAL(9,C18:C25) -> 64205 | F27: =SUBTOTAL(9,F18:F25) -> 0 | H27: =SUBTOTAL(9,H18:H25) -> 64205
A28: Total Revenue | B28: 415963.13 | C28: =SUBTOTAL(9,C7:C25) -> 569408.54 | F28: =SUBTOTAL(9,F7:F25) -> 86628.173 | H28: =SUBTOTAL(9,H7:H25) -> 656036.71
A30: Expenses
A31: Officers Salary | B31: 200002.16 | C31: ='June-26 TTM '!B35 -> 183335.48 | F31: ='Employee Roster'!S8-'Pro Forma Financials'!C31 -> 66664.52 | H31: =C31+F31 -> 250000 | J31: MMA: Set Judy to go forward compensation structure
A32: Shareholders | B32: 200002.16 | C32: =SUBTOTAL(9,C31:C31) -> 183335.48 | F32: =SUBTOTAL(9,F31:F31) -> 66664.52 | H32: =SUBTOTAL(9,H31:H31) -> 250000
B35: 0 | C35: =IFERROR(INDEX([1]PF_Input!$B$9:$F$89,MATCH($A35,[1]PF_Input!$B$9:$B$89,0),MATCH(C$3,[1]PF_Input!$B$5:$F$5,0)),0) -> 0 | F35: 0
B36: 0 | C36: =IFERROR(INDEX([1]PF_Input!$B$9:$F$89,MATCH($A36,[1]PF_Input!$B$9:$B$89,0),MATCH(C$3,[1]PF_Input!$B$5:$F$5,0)),0) -> 0 | F36: 0
A37: Staff Wages | B37: 122550.59 | C37: ='June-26 TTM '!B38 -> 124914.82 | F37: ='Employee Roster'!S24-'Pro Forma Financials'!C37 -> -14664.82 | H37: =C37+F37 -> 110250 | J37: MMA: Set to salary roster
A38: Staff & Support | B38: 122550.59 | C38: =SUBTOTAL(9,C35:C37) -> 124914.82 | F38: =SUBTOTAL(9,F35:F37) -> -14664.82 | H38: =SUBTOTAL(9,H35:H37) -> 110250
A40: Compensation Expense | B40: 322552.75 | C40: =SUBTOTAL(9,C31:C38) -> 308250.3 | F40: =SUBTOTAL(9,F31:F38) -> 51999.7 | H40: =SUBTOTAL(9,H31:H38) -> 360250
B42: 0 | C42: =IFERROR(INDEX([1]PF_Input!$B$9:$F$89,MATCH($A42,[1]PF_Input!$B$9:$B$89,0),MATCH(C$3,[1]PF_Input!$B$5:$F$5,0)),0) -> 0 | F42: 0
B43: 0 | C43: =IFERROR(INDEX([1]PF_Input!$B$9:$F$89,MATCH($A43,[1]PF_Input!$B$9:$B$89,0),MATCH(C$3,[1]PF_Input!$B$5:$F$5,0)),0) -> 0 | F43: 0
A44: Health Insurance | B44: 0 | C44: =IFERROR(INDEX([1]PF_Input!$B$9:$F$89,MATCH($A44,[1]PF_Input!$B$9:$B$89,0),MATCH(C$3,[1]PF_Input!$B$5:$F$5,0)),0) -> 0 | F44: ='Employee Roster'!AC26 -> 34800 | H44: =C44+F44 -> 34800 | J44: MMA: Set to MMA PCS National benefits
A45: Medical Insurance | B45: 0 | C45: =SUBTOTAL(9,C42:C44) -> 0 | F45: =SUBTOTAL(9,F42:F44) -> 34800 | H45: =SUBTOTAL(9,H42:H44) -> 34800
B47: 0 | C47: =IFERROR(INDEX([1]PF_Input!$B$9:$F$89,MATCH($A47,[1]PF_Input!$B$9:$B$89,0),MATCH(C$3,[1]PF_Input!$B$5:$F$5,0)),0) -> 0 | F47: 0
B48: 0 | C48: =IFERROR(INDEX([1]PF_Input!$B$9:$F$89,MATCH($A48,[1]PF_Input!$B$9:$B$89,0),MATCH(C$3,[1]PF_Input!$B$5:$F$5,0)),0) -> 0 | F48: 0
A49: Payroll Taxes | B49: 26816.6 | C49: ='June-26 TTM '!B37 -> 23961.38 | F49: ='Employee Roster'!AA26-'Pro Forma Financials'!C49 -> -463.255 | H49: =C49+F49 -> 23498.125 | J49: MMA: Recalculate payroll taxes
A50: Payroll Taxes | B50: 26816.6 | C50: =SUBTOTAL(9,C47:C49) -> 23961.38 | F50: =SUBTOTAL(9,F47:F49) -> -463.255 | H50: =SUBTOTAL(9,H47:H49) -> 23498.125
B52: 0 | C52: =IFERROR(INDEX([1]PF_Input!$B$9:$F$89,MATCH($A52,[1]PF_Input!$B$9:$B$89,0),MATCH(C$3,[1]PF_Input!$B$5:$F$5,0)),0) -> 0 | F52: 0
B53: 0 | C53: =IFERROR(INDEX([1]PF_Input!$B$9:$F$89,MATCH($A53,[1]PF_Input!$B$9:$B$89,0),MATCH(C$3,[1]PF_Input!$B$5:$F$5,0)),0) -> 0 | F53: 0
A54: Employee Retirement Plans | B54: 1850 | C54: =IFERROR(INDEX([1]PF_Input!$B$9:$F$89,MATCH($A54,[1]PF_Input!$B$9:$B$89,0),MATCH(C$3,[1]PF_Input!$B$5:$F$5,0)),0) -> 0 | F54: ='Employee Roster'!AB26 -> 12200 | H54: =C54+F54 -> 12200 | J54: MMA: Set to MMA National 401k plan (50% match up to 8% of base salary, effectively 4%)
A55: Retirement | B55: 1850 | C55: =SUBTOTAL(9,C52:C54) -> 0 | F55: =SUBTOTAL(9,F52:F54) -> 12200 | H55: =SUBTOTAL(9,H52:H54) -> 12200
A57: Benefits Expense | B57: 28666.6 | C57: =SUBTOTAL(9,C42:C55) -> 23961.38 | F57: =SUBTOTAL(9,F42:F55) -> 46536.745 | H57: =SUBTOTAL(9,H42:H55) -> 70498.125
...

Sheet Book of Business
A1: Insured | B1: Ex. Date | C1: Coverage | D1: Carrier | E1: Wholesaler | F1: Liab Limit | G1: Premium | H1: Commission | I1: Monthly Premium Totals | J1: BP Pymt | K1: IPFS+misc
A2: Pisces | B2: 45658 | C2: PNC | E2: Element | G2: 100000 | H2: 10000
A3: ATFO, LLC | B3: 44562 | C3: TREO | D3: Nomadx | E3: ARC | F3: $1M | G3: 13125
A4: Atinaw, LLC | B4: 44562 | C4: TREO | D4: Nomadx | E4: ARC | F4: $1M | G4: 8925
A5: Duncan & John C Schmidt | B5: 44927 | C5: TREO | D5: Nomadx | E5: ARC | F5: $1M | G5: 2625
A6: LB Business Services | B6: 44930 | C6: TREO | D6: AWAC | E6: ARC | F6: $1M | G6: 1700 | H6: =G6*0.12 -> 204
A7: Laura Fisher (Pisces) | B7: 46027 | C7: Sexual Misconduct | D7: Lloyds | E7: ARC | F7: $1M | G7: 6291 | H7: =G7*12.5% -> 786.375
A8: Laura Fisher (Pisces) | B8: 46027 | C8: EO | D8: Allied Medical | E8: ARC | F8: $3M | G8: 2520 | H8: =G8*12.5% -> 315
A9: Laura Fisher (Pisces) | B9: 46027 | C9: XS EO | D9: Nautilus | E9: ARC | F9: $1M | G9: 9589.97 | H9: =G9*12.5% -> 1198.7462
A10: Laura Fisher (Pisces) | B10: 46027 | C10: XS EO | D10: Hadron | E10: ARC | F10: $2M | G10: 4728.49 | H10: =G10*12.5% -> 591.06125
A11: Investors Preferred | B11: 44942 | C11: FI PKG | D11: Lloyds | E11: RT | F11: $1M | G11: 44127.66 | H11: =G11*11.5% -> 5074.6809
A12: Investors Preferred | B12: 44942 | C12: FI Bond | D12: XL Specialty | E12: ARC | F12: $5M | G12: 8546 | H12: =G12*12.5% -> 1068.25
A13: Hermes Trust Co | B13: 45676 | C13: EO/DO | D13: CNA | E13: ARC | F13: $5M | G13: 48000 | H13: =G13*12.5% -> 6000
A14: Hermes Trust Co | B14: 45676 | C14: FI Bond | D14: CNA | E14: ARC | F14: $4M | G14: 11649 | H14: =G14*12.5% -> 1456.125
A15: Hermes Trust Co | B15: 45676 | C15: Cyber | D15: At Bay | E15: ARC | F15: $2M | G15: 11199.79 | H15: =G15*12.5% -> 1399.9738
A16: City Fields Foundation (Pisces) | B16: 45683 | C16: DO | D16: Scottsdale | E16: ARC | F16: $5M | G16: 4200 | H16: =G16*12.5% -> 525
A17: The Lions Consulting Group | B17: 45684 | C17: TREO | D17: AWAC | E17: ARC | F17: $1M | G17: 1031.75 | H17: =G17*0.125 -> 128.96875
A18: Shock the System | B18: 46049 | C18: DO | D18: Lexington | E18: ARC | F18: $1M | G18: 8886.89 | H18: =G18*0.125 -> 1110.8612
A19: Independent Trustee Alliance/ Kevin Quinn | B19: 44955 | C19: Association Professional | D19: Gemini | E19: ARC | F19: $1M | G19: 1538.74 | H19: =G19*0.125 -> 192.3425
A20: Independent Trustee Alliance/ Kevin Quinn | B20: 44955 | C20: Cyber | D20: At Bay | E20: ARC | F20: $1M | G20: 1048.9 | H20: =G20*0.125 -> 131.1125
A21: Independent Trustee Alliance/ Kevin Quinn | B21: 44955 | C21: D&O | D21: Arch | E21: ARC | F21: $1M | G21: 869 | H21: =G21*12.5% -> 108.625
I22: =SUM(H2:H22) -> 30291.122 | J22: 5975.05 | K22: 99.6
A23: ILS (interactive Legal Services) | B23: 44959 | C23: Cyber | D23: CFC | E23: ARC | F23: $5M | G23: 12000 | H23: =G23*11% -> 1320
A24: ILS (interactive Legal Services) | B24: Feb 2, 2027 | C24: DO | D24: Zurich | E24: ARC | F24: $2M | G24: 3747 | H24: =G24*12% -> 449.64
A25: EBOR (WSG(PTC)) | B25: Feb 2 | C25: Private Trust Co | D25: Travelers | E25: RT | F25: $5M | G25: 106777 | H25: =G25*12% -> 12813.24
A26: Lakeside Accounting Solutions, LLC | B26: 45693 | C26: EO | D26: Houston Casualty | E26: ARC | F26: $1M | G26: 1856 | H26: =G26*12.5% -> 232
A27: South Dakota Trust Association | B27: 44964 | C27: D&O | D27: Travelers | E27: ARC | F27: $1M | G27: 1775 | H27: =G27*12.5% -> 221.875
A28: Center of the Golden One | B28: 46073 | C28: Cyber | D28: CFC | E28: ARC | F28: $1M | G28: 1295 | H28: =G28*12.5% -> 161.875
A29: TEFAF | B29: 45342 | C29: GL/Spectator Accident | D29: HCC | E29: ProSight | F29: $5M | G29: 6313 | H29: =G29*0.1 -> 631.3
A30: TEFAF | B30: 46073 | C30: Exhibitor | D30: HCC | E30: K&K | F30: TBD
A31: TEFAF | B31: 46073 | C31: Event Cancellation | D31: HCC | E31: Affinity | F31: 7761000 | G31: 45706 | H31: 6855.9
A32: TEFAF | B32: 45708 | C32: Fee | H32: 5000
A33: Chandler Trust | B33: 45344 | C33: EO/DO | D33: Texas Insurance Co | E33: ARC | F33: $2.5M | G33: 142500 | H33: =G33*0.125 -> 17812.5
A34: Chandler Trust | B34: 45344 | C34: EO/DO | D34: Crum & Forster | E34: ARC | F34: $2.5M | G34: 71250 | H34: =G34*0.125 -> 8906.25
A35: Chandler Trust | B35: 45344 | C35: EO/DO | D35: Coaction | E35: ARC | F35: $5M | G35: 95562 | H35: =G35*0.125 -> 11945.25
A36: Chandler Trust | B36: 45344 | C36: EO/DO | D36: XL Specialty | E36: ARC | F36: $5M | G36: 67500 | H36: =G36*0.125 -> 8437.5
A37: Chandler Trust | B37: 45344 | C37: EO/DO | D37: Convex | E37: ARC | F37: $5M | G37: 50250 | H37: =G37*0.125 -> 6281.25
A38: Chandler Trust | B38: 45344 | C38: EO/DO | D38: Hanover Insurance Company | E38: ARC | F38: $5M | G38: 40199.06 | H38: =G38*0.125 -> 5024.8825
A39: Chandler Trust | B39: 45344 | C39: EO/DO | D39: CNA | E39: ARC | F39: $5M | G39: 33772 | H39: =G39*0.125 -> 4221.5
A40: Chandler Trust | B40: 45344 | C40: EO/DO | D40: Ascot | E40: ARC | F40: $5M/$20M | G40: 26250 | H40: =G40*0.125 -> 3281.25
...

Sheet Employee Roster
B1: Project Rocky - Employee Roster
F3: Book of | H3: Reported | L3: Seller Pro Forma | P3: MMA Pro Forma | U3: Variance | W3: Variance | Y3: Social | AA3: Payroll
C4: $ | D4: Name | E4: Title | F4: Business | H4: Base | I4: Comm. | J4: Bonus | K4: Total | L4: Base | M4: Comm. | N4: Bonus | O4: Total | P4: Base | Q4: Comm. | R4: Bonus | S4: Total | U4: to Reported | W4: to Seller PF | Y4: Security | Z4: Medicare | AA4: Taxes | AB4: 401(k) | AC4: Medical
C6: 1 | D6: Judy Pearson | E6: Principal | F6: ='Pro Forma Financials'!H16 -> 591831.71 | H6: 200000 | I6: 0 | J6: 0 | K6: =SUM(H6:J6) -> 200000 | L6: 0 | M6: 0 | N6: 0 | O6: =SUM(L6:N6) -> 0 | P6: 200000 | R6: =P6*25% -> 50000 | S6: =SUM(P6:R6) -> 250000 | U6: =S6-K6 -> 50000 | W6: =+S6-O6 -> 250000 | Y6: =$AC$34*MIN($S6,$AC$33) -> 11439 | Z6: =$AC$37*$S6 -> 3625 | AA6: =SUM(Y6:Z6) -> 15064 | AB6: =$AC$41*MIN(P6+Q6,$AC$40) -> 8000 | AC6: =IF($S6>0,IF($S$49=1,$S$46,$S$44),0) -> 11600
D7: Unreconciled variance | F7: 0 | H7: 0 | I7: 0 | J7: 0 | L7: 0 | M7: 0 | N7: 0 | O7: =SUM(L7:N7) -> 0 | P7: 0 | Q7: 0 | R7: 0 | S7: =SUM(P7:R7) -> 0 | U7: =S7-K7 -> 0 | W7: =+S7-O7 -> 0 | Z7: =$AC$37*$S7 -> 0 | AA7: =SUM(Y7:Z7) -> 0
C8: Total Shareholders | F8: =SUM(F6:F7) -> 591831.71 | H8: =SUM(H6:H7) -> 200000 | I8: =SUM(I6:I7) -> 0 | J8: =SUM(J6:J7) -> 0 | K8: =SUM(K6:K7) -> 200000 | L8: =SUM(L6:L7) -> 0 | M8: =SUM(M6:M7) -> 0 | N8: =SUM(N6:N7) -> 0 | O8: =SUM(O6:O7) -> 0 | ... S8: =SUM(S6:S7) -> 250000 | U8: =SUM(U6:U7) -> 50000 | W8: =SUM(W6:W7) -> 250000 | Y8: =SUM(Y6:Y7) -> 11439 | Z8: =SUM(Z6:Z7) -> 3625 | AA8: =SUM(AA6:AA7) -> 15064 | AB8: =SUM(AB6:AB7) -> 8000 | AC8: =SUM(AC6:AC7) -> 11600
C10: =MAX($C$6:$C9)+1 -> 2 | F10: 0 | H10: 0 | I10: 0 | J10: 0 | K10: =SUM(H10:J10) -> 0 | L10: 0 | M10: 0 | N10: 0 | O10: =SUM(L10:N10) -> 0 | P10: 0 | Q10: 0 | R10: 0 | S10: =SUM(P10:R10) -> 0 | U10: =S10-K10 -> 0 | W10: =+S10-O10 -> 0 | Y10: =$AC$34*MIN($S10,$AC$33) -> 0 | Z10: =$AC$37*$S10 -> 0 | AA10: =SUM(Y10:Z10) -> 0 | AB10: =$AC$41*MIN(P10+Q10,$AC$40) -> 0 | AC10: =IF($S10>0,IF($S$49=1,$S$46,$S$44),0) -> 0
C11: =MAX($C$6:$C10)+1 -> 3 | F11: 0 | H11: 0 | I11: 0 | J11: 0 | K11: =SUM(H11:J11) -> 0 | L11: 0 | M11: 0 | N11: 0 | O11: =SUM(L11:N11) -> 0 | P11: 0 | Q11: 0 | R11: 0 | S11: =SUM(P11:R11) -> 0 | U11: =S11-K11 -> 0 | W11: =+S11-O11 -> 0 | Y11: =$AC$34*MIN($S11,$AC$33) -> 0 | Z11: =$AC$37*$S11 -> 0 | AA11: =SUM(Y11:Z11) -> 0 | AB11: =$AC$41*MIN(P11+Q11,$AC$40) -> 0 | AC11: =IF($S11>0,IF($S$49=1,$S$46,$S$44),0) -> 0
C12: =MAX($C$6:$C11)+1 -> 4 | F12: 0 | H12: 0 | I12: 0 | J12: 0 | K12: =SUM(H12:J12) -> 0 | L12: 0 | M12: 0 | N12: 0 | O12: =SUM(L12:N12) -> 0 | P12: 0 | Q12: 0 | R12: 0 | S12: =SUM(P12:R12) -> 0 | U12: =S12-K12 -> 0 | W12: =+S12-O12 -> 0 | Y12: =$AC$34*MIN($S12,$AC$33) -> 0 | Z12: =$AC$37*$S12 -> 0 | AA12: =SUM(Y12:Z12) -> 0 | AB12: =$AC$41*MIN(P12+Q12,$AC$40) -> 0 | AC12: =IF($S12>0,IF($S$49=1,$S$46,$S$44),0) -> 0
C13: =MAX($C$6:$C12)+1 -> 5 | F13: 0 | H13: 0 | I13: 0 | J13: 0 | K13: =SUM(H13:J13) -> 0 | L13: 0 | M13: 0 | N13: 0 | O13: =SUM(L13:N13) -> 0 | P13: 0 | Q13: 0 | R13: 0 | S13: =SUM(P13:R13) -> 0 | U13: =S13-K13 -> 0 | W13: =+S13-O13 -> 0 | Y13: =$AC$34*MIN($S13,$AC$33) -> 0 | Z13: =$AC$37*$S13 -> 0 | AA13: =SUM(Y13:Z13) -> 0 | AB13: =$AC$41*MIN(P13+Q13,$AC$40) -> 0 | AC13: =IF($S13>0,IF($S$49=1,$S$46,$S$44),0) -> 0
D14: Unreconciled variance | F14: 0 | H14: 0 | I14: 0 | J14: 0 | K14: =[1]PF_Schedule!G58-SUM('Employee Roster'!K10:K13) -> 0 | L14: 0 | M14: 0 | N14: 0 | O14: =SUM(L14:N14) -> 0 | P14: 0 | Q14: 0 | R14: 0 | S14: =SUM(P14:R14) -> 0 | U14: =S14-K14 -> 0 | W14: =+S14-O14 -> 0
C15: Total Non-Shareholder Producers | F15: =SUM(F10:F14) -> 0 | H15: =SUM(H10:H14) -> 0 | I15: =SUM(I10:I14) -> 0 | J15: =SUM(J10:J14) -> 0 | K15: =SUM(K10:K14) -> 0 | L15: =SUM(L10:L14) -> 0 | M15: =SUM(M10:M14) -> 0 | N15: =SUM(N10:N14) -> 0 | O15: =SUM(O10:O14) -> 0 | ... S15: =SUM(S10:S14) -> 0 | U15: =SUM(U10:U14) -> 0 | W15: =SUM(W10:W14) -> 0 | Y15: =SUM(Y10:Y14) -> 0 | Z15: =SUM(Z10:Z14) -> 0 | AA15: =SUM(AA10:AA14) -> 0 | AB15: =SUM(AB10:AB14) -> 0 | AC15: =SUM(AC10:AC14) -> 0
C17: 2 | D17: Alex Gruitch | E17: Associate AM | F17: 0 | H17: 60000 | I17: 0 | J17: 0 | K17: =SUM(H17:J17) -> 60000 | L17: 0 | M17: 0 | N17: 0 | O17: =SUM(L17:N17) -> 0 | P17: =+H17 -> 60000 | Q17: 0 | R17: =+P17*0.05 -> 3000 | S17: =SUM(P17:R17) -> 63000 | U17: =S17-K17 -> 3000 | W17: =+S17-O17 -> 63000 | Y17: =$AC$34*MIN($S17,$AC$33) -> 3906 | Z17: =$AC$37*$S17 -> 913.5 | AA17: =SUM(Y17:Z17) -> 4819.5 | AB17: =$AC$41*MIN(P17+Q17,$AC$40) -> 2400 | AC17: =IF($S17>0,IF($S$49=1,$S$46,$S$44),0) -> 11600
C18: 3 | D18: Replacement hire for Liam Franks | E18: Associate AM | F18: 0 | H18: 45000 | I18: 0 | J18: 0 | K18: =SUM(H18:J18) -> 45000 | L18: 0 | M18: 0 | N18: 0 | O18: =SUM(L18:N18) -> 0 | P18: =H18 -> 45000 | Q18: 0 | R18: =+P18*0.05 -> 2250 | S18: =SUM(P18:R18) -> 47250 | U18: =S18-K18 -> 2250 | W18: =+S18-O18 -> 47250 | Y18: =$AC$34*MIN($S18,$AC$33) -> 2929.5 | Z18: =$AC$37*$S18 -> 685.125 | AA18: =SUM(Y18:Z18) -> 3614.625 | AB18: =$AC$41*MIN(P18+Q18,$AC$40) -> 1800 | AC18: =IF($S18>0,IF($S$49=1,$S$46,$S$44),0) -> 11600
C19: =MAX($C$6:$C18)+1 -> 6 | F19: 0 | H19: 0 | I19: 0 | J19: 0 | K19: =SUM(H19:J19) -> 0 | L19: 0 | M19: 0 | N19: 0 | O19: =SUM(L19:N19) -> 0 | P19: 0 | Q19: 0 | R19: 0 | S19: =SUM(P19:R19) -> 0 | U19: =S19-K19 -> 0 | W19: =+S19-O19 -> 0 | Y19: =$AC$34*MIN($S19,$AC$33) -> 0 | Z19: =$AC$37*$S19 -> 0 | AA19: =SUM(Y19:Z19) -> 0 | AB19: =$AC$41*MIN(P19+Q19,$AC$40) -> 0 | AC19: =IF($S19>0,IF($S$49=1,$S$46,$S$44),0) -> 0
C20: =MAX($C$6:$C19)+1 -> 7 | F20: 0 | H20: 0 | I20: 0 | J20: 0 | K20: =SUM(H20:J20) -> 0 | L20: 0 | M20: 0 | N20: 0 | O20: =SUM(L20:N20) -> 0 | P20: 0 | Q20: 0 | R20: 0 | S20: =SUM(P20:R20) -> 0 | U20: =S20-K20 -> 0 | W20: =+S20-O20 -> 0 | Y20: =$AC$34*MIN($S20,$AC$33) -> 0 | Z20: =$AC$37*$S20 -> 0 | AA20: =SUM(Y20:Z20) -> 0 | AB20: =$AC$41*MIN(P20+Q20,$AC$40) -> 0 | AC20: =IF($S20>0,IF($S$49=1,$S$46,$S$44),0) -> 0
C21: =MAX($C$6:$C20)+1 -> 8 | F21: 0 | H21: 0 | I21: 0 | J21: 0 | K21: =SUM(H21:J21) -> 0 | L21: 0 | M21: 0 | N21: 0 | O21: =SUM(L21:N21) -> 0 | P21: 0 | Q21: 0 | R21: 0 | S21: =SUM(P21:R21) -> 0 | U21: =S21-K21 -> 0 | W21: =+S21-O21 -> 0 | Y21: =$AC$34*MIN($S21,$AC$33) -> 0 | Z21: =$AC$37*$S21 -> 0 | AA21: =SUM(Y21:Z21) -> 0 | AB21: =$AC$41*MIN(P21+Q21,$AC$40) -> 0 | AC21: =IF($S21>0,IF($S$49=1,$S$46,$S$44),0) -> 0
C22: =MAX($C$6:$C21)+1 -> 9 | E22: Terminated | F22: 0 | H22: 0 | I22: 0 | J22: 0 | K22: =SUM(H22:J22) -> 0 | L22: 0 | M22: 0 | N22: 0 | O22: =SUM(L22:N22) -> 0 | P22: 0 | Q22: 0 | R22: 0 | S22: =SUM(P22:R22) -> 0 | U22: =S22-K22 -> 0 | W22: =+S22-O22 -> 0 | Y22: =$AC$34*MIN($S22,$AC$33) -> 0 | Z22: =$AC$37*$S22 -> 0 | AA22: =SUM(Y22:Z22) -> 0 | AB22: =$AC$41*MIN(P22+Q22,$AC$40) -> 0 | AC22: =IF($S22>0,IF($S$49=1,$S$46,$S$44),0) -> 0
D23: Unreconciled difference to P&L | F23: 0 | H23: 0 | I23: 0 | J23: 0 | L23: 0 | M23: 0 | N23: 0 | O23: =SUM(L23:N23) -> 0 | P23: 0 | Q23: 0 | R23: 0 | S23: =SUM(P23:R23) -> 0 | U23: =S23-K23 -> 0 | W23: =+S23-O23 -> 0
C24: Total Staff & Support | F24: =SUM(F17:F23) -> 0 | H24: =SUM(H17:H23) -> 105000 | I24: =SUM(I17:I23) -> 0 | J24: =SUM(J17:J23) -> 0 | K24: =SUM(K17:K23) -> 105000 | L24: =SUM(L17:L23) -> 0 | M24: =SUM(M17:M23) -> 0 | N24: =SUM(N17:N23) -> 0 | O24: =SUM(O17:O23) -> 0 | ... S24: =SUM(S17:S23) -> 110250 | U24: =SUM(U17:U23) -> 5250 | W24: =SUM(W17:W23) -> 110250 | Y24: =SUM(Y17:Y23) -> 6835.5 | Z24: =SUM(Z17:Z23) -> 1598.625 | AA24: =SUM(AA17:AA23) -> 8434.125 | AB24: =SUM(AB17:AB23) -> 4200 | AC24: =SUM(AC17:AC23) -> 23200
C26: Total Compensation | F26: =F8+F15+F24 -> 591831.71 | H26: =H8+H15+H24 -> 305000 | I26: =I8+I15+I24 -> 0 | J26: =J8+J15+J24 -> 0 | K26: =K8+K15+K24 -> 305000 | L26: =L8+L15+L24 -> 0 | M26: =M8+M15+M24 -> 0 | N26: =N8+N15+N24 -> 0 | O26: =O8+O15+O24 -> 0 | ... S26: =S8+S15+S24 -> 360250 | U26: =U8+U15+U24 -> 55250 | W26: =W8+W15+W24 -> 360250 | Y26: =Y8+Y15+Y24 -> 18274.5 | Z26: =Z8+Z15+Z24 -> 5223.625 | AA26: =AA8+AA15+AA24 -> 23498.125 | AB26: =AB8+AB15+AB24 -> 12200 | AC26: =AC8+AC15+AC24 -> 34800
C28: Per Source | F28: ='Pro Forma Financials'!H11 -> 591831.71 | K28: ='Pro Forma Financials'!C40 -> 308250.3 | S28: =S26 -> 360250 | AA28: ='Pro Forma Financials'!H49 -> 23498.125 | AB28: ='Pro Forma Financials'!H54 -> 12200 | AC28: ='Pro Forma Financials'!H44 -> 34800
C29: Variance | F29: =+F26-F28 -> 0 | K29: =+K26-K28 -> -3250.3 | O29: =+O26-O28 -> 0 | S29: =+S26-S28 -> 0 | AA29: =+AA26-AA28 -> 0 | AB29: =+AB26-AB28 -> 0 | AC29: =+AC26-AC28 -> 0
P31: Commission Assumptions | Y31: Benefit Assumptions
P32: Book Split | Y32: Social Security
P33: Growth Business | S33: 0.1 | Y33: Income Limit | AC33: 184500
P34: Base Business | S34: 0.9 | Y34: Social Security Tax Rate | AC34: 0.062
P36: Commission Structure | Y36: Medicare
P37: Commission on Growth | S37: 0.4 | Y37: Medicare Tax Rate | AC37: 0.0145
P38: Commission on Base | S38: 0.25
P39: Assumed Commission Percentage | S39: =SUMPRODUCT(S33:S34,S37:S38) -> 0.265 | Y39: 401(k)
Y40: Income Limit | AC40: 360000
P41: Benefits comparison | Y41: MMA Match Rate | AC41: =8%*0.5 -> 0.04
P42: Reported | S42: =[1]PF_Schedule!G70 -> 0
P43: Number of EEs | S43: =MAX(C6:C24) -> 9 | Y43: Medical
P44: Per EE | S44: =S42/S43 -> 0 | Y44: Cost per Employee | AC44: =ROUND(VLOOKUP([1]Inputs!H14,'[1]Benefit Cost by Region'!$A$20:$D$31,4,FALSE),-2) -> 11600
P46: MMA Region | S46: =ROUND(VLOOKUP([1]Inputs!H14,'[1]Benefit Cost by Region'!$A$20:$D$31,4,FALSE),-2) -> 11600 | Y46: Staff Bonus
P47: Variance | S47: =S44-S46 -> -11600 | Y47: Bonus per Employee | AC47: 0.03
P49: Benefits Toggle (1 = MMA plan) | S49: 1

Sheet June-26 TTM 
A1: Project Rocky
A2: Income Statement
B5: June 2026 TTM
A6: Income
A7: Sales | B7: 569203.54
A8: Total for Income | B8: =B6+B7 -> 569203.54
A9: Gross Profit | B9: =B8-0 -> 569203.54
A10: Expenses
A11: Advertising & marketing | B11: 510.76
A12: Business licenses | B12: 1871.7
A13: Dues and Memberships | B13: 6147
A14: Employee benefits | B14: 4150
A15: Employee Expense Reimbursement | B15: 457.72
A16: General business expenses | B16: 14.35
A17: Bank fees & service charges | B17: 242.16
A18: Continuing education | B18: 7652.27
A19: Memberships & subscriptions | B19: 99
A20: Total for General business expenses | B20: =B16+B17+B18+B19 -> 8007.78
A21: Insurance | B21: 9381.85
A22: Legal & accounting services | B22: 97.85
A23: Accounting fees | B23: 4007.78
A24: Legal fees | B24: 5295.51
A25: Total for Legal & accounting services | B25: =B22+B23+B24 -> 9401.14
A26: Meals | B26: 5098
A27: Meals with clients | B27: 18.05
A28: Total for Meals | B28: =B26+B27 -> 5116.05
A29: Office expenses | B29: 340.42
A30: Office supplies | B30: 3389.49
A31: Shipping & postage | B31: 233.61
A32: Software, IT & apps | B32: 24553.15
A33: Total for Office expenses | B33: =B29+B30+B31+B32 -> 28516.67
A34: Payroll expenses
A35: Officers Salary | B35: 183335.48
A36: Payroll Fees | B36: 1047.1
A37: Payroll taxes (Company) | B37: 23961.38
A38: Staff Wages | B38: 124914.82
A39: Total for Payroll expenses | B39: =B34+B35+B36+B37+B38 -> 333258.78
A40: Professional Services | B40: 2705.8
A41: Rent | B41: 5882.4
A42: OFF RENT | B42: 239.88
...

Sheet 2024 BS
A1: Precision Brokers, LLC
A2: Balance Sheet
A3: As of Dec 31, 2024
B5: Total
A6: Assets
A7: Current Assets
A8: Bank Accounts
A9: Chase Business Operating 2157 | B9: 32280.77
A10: Chase Premium 5805 | B10: 98960.65
A11: Total for Bank Accounts | B11: =B8+B9+B10 -> 131241.42
A12: Accounts Receivable
A13: Accounts Receivable (A/R) | B13: 30476.74
A14: Total for Accounts Receivable | B14: =B12+B13 -> 30476.74
A15: Total for Current Assets | B15: =B7+B11+B14 -> 161718.16
A16: Total for Assets | B16: =B6+B15 -> 161718.16
A17: Liabilities and Equity
A18: Liabilities
A19: Current Liabilities
A20: Credit Cards
A21: Chase - Brudnicki 8695 | B21: 0
A22: Chase Credit Card - United 8687 | B22: 4021.45
A23: Total for Credit Cards | B23: =B20+B21+B22 -> 4021.45
A24: Other Current Liabilities
A25: Commissions Due to Precision | B25: -45847.39
A26: Insurance Premiums Owed | B26: 175314.78
A27: Total for Other Current Liabilities | B27: =B24+B25+B26 -> 129467.39
A28: Total for Current Liabilities | B28: =B19+B23+B27 -> 133488.84
A29: Total for Liabilities | B29: =B18+B28 -> 133488.84
A30: Equity
A31: Opening balance equity | B31: 0
A32: Retained Earnings
A33: Net Income | B33: 28229.32
A34: Total for Equity | B34: =B30+B31+B32+B33 -> 28229.32
A35: Total for Liabilities and Equity | B35: =B17+B29+B34 -> 161718.16
A37: Footnote: Precision Brokers’ balance sheet reflects both client premiums receivable and premiums payable to carriers. The portion of premiums representing commissions due to Precision is recorded as an offset against the carrier liability, reducing the total payable balance. Revenue is recognized when commissions are swept from the premium trust account to the operating account, at which point the income statement reflects earned commissions.
A39: Accrual Basis Wednesday, July 29, 2026 11:36 AM GMT-06:00

Sheet 2025 BS
A1: Precision Brokers, LLC
A2: Balance Sheet
A3: As of Dec 31, 2025
B5: Total
A6: Assets
A7: Current Assets
A8: Bank Accounts
A9: Chase Business Operating 2157 | B9: 27489.49
A10: Chase Premium 5805 | B10: 248798.66
A11: Operating Cash (Trust Restricted) | B11: 13293.71
A12: Operating Cash (Unrestricted) | B12: -13293.71
A13: Total for Bank Accounts | B13: =B8+B9+B10+B11+B12 -> 276288.15
A14: Accounts Receivable
A15: Accounts Receivable (A/R) | B15: 244788.89
A16: Total for Accounts Receivable | B16: =B14+B15 -> 244788.89
A17: Other Current Assets
A18: Payments to deposit | B18: 0
A19: Total for Other Current Assets | B19: =B17+B18 -> 0
A20: Total for Current Assets | B20: =B7+B13+B16+B19 -> 521077.04
A21: Fixed Assets
A22: Computer and Hardware | B22: 2233.7
A23: Total for Fixed Assets | B23: =B21+B22 -> 2233.7
A24: Other Assets
A25: Security deposits | B25: 5546.04
A26: Total for Other Assets | B26: =B24+B25 -> 5546.04
A27: Total for Assets | B27: =B6+B20+B23+B26 -> 528856.78
A28: Liabilities and Equity
A29: Liabilities
A30: Current Liabilities
A31: Credit Cards
A32: Chase - Brudnicki 8695 | B32: 0
A33: Chase Credit Card - United 8687 | B33: 49.42
A34: Total for Credit Cards | B34: =B31+B32+B33 -> 49.42
A35: Other Current Liabilities
A36: Commissions Due to Precision | B36: -281589.91
A37: Insurance Premiums Owed | B37: 788471.17
A38: Total for Other Current Liabilities | B38: =B35+B36+B37 -> 506881.26
A39: Total for Current Liabilities | B39: =B30+B34+B38 -> 506930.68
A40: Total for Liabilities | B40: =B29+B39 -> 506930.68
A41: Equity
...

Sheet Trending Balance Sheet
A1: Project Rocky
A2: Trending Balance Sheet
B5: 2024 | C5: 2025 | D5: As of Jun 30, 2026
A6: Assets
A7: Current Assets
A8: Bank Accounts
A9: Chase Business Operating 2157 | B9: ='2024 BS'!B9 -> 32280.77 | C9: ='2025 BS'!B9 -> 27489.49 | D9: 117004.95
A10: Chase Premium 5805 | B10: ='2024 BS'!B10 -> 98960.65 | C10: ='2025 BS'!B10 -> 248798.66 | D10: 32739.54
A11: Operating Cash (Trust Restricted) | C11: ='2025 BS'!B11 -> 13293.71 | D11: 13293.71
A12: Operating Cash (Unrestricted) | C12: ='2025 BS'!B12 -> -13293.71 | D12: -13293.71
A13: Total for Bank Accounts | B13: =B8+B9+B10+B11+B12 -> 131241.42 | C13: =C8+C9+C10+C11+C12 -> 276288.15 | D13: =D8+D9+D10+D11+D12 -> 149744.49
A14: Accounts Receivable
A15: Accounts Receivable (A/R) | B15: ='2024 BS'!B13 -> 30476.74 | C15: ='2025 BS'!B15 -> 244788.89 | D15: 25944.12
A16: Total for Accounts Receivable | B16: =B14+B15 -> 30476.74 | C16: =C14+C15 -> 244788.89 | D16: =D14+D15 -> 25944.12
A17: Other Current Assets
A18: Payments to deposit | C18: ='2025 BS'!B18 -> 0 | D18: 0
A19: Total for Other Current Assets | C19: =C17+C18 -> 0 | D19: =D17+D18 -> 0
A20: Total for Current Assets | C20: =C7+C13+C16+C19 -> 521077.04 | D20: =D7+D13+D16+D19 -> 175688.61
A21: Fixed Assets
A22: Computer and Hardware | C22: ='2025 BS'!B22 -> 2233.7 | D22: 2233.7
A23: Total for Fixed Assets | C23: =C21+C22 -> 2233.7 | D23: =D21+D22 -> 2233.7
A24: Other Assets
A25: Security deposits | C25: ='2025 BS'!B25 -> 5546.04 | D25: 9068.13
A26: Total for Other Assets | C26: =C24+C25 -> 5546.04 | D26: =D24+D25 -> 9068.13
A27: Total for Assets | C27: =C6+C20+C23+C26 -> 528856.78 | D27: =D6+D20+D23+D26 -> 186990.44
A28: Liabilities and Equity
A29: Liabilities
A30: Current Liabilities
A31: Credit Cards
A32: Chase - Brudnicki 8695 | B32: ='2024 BS'!B21 -> 0 | C32: ='2025 BS'!B32 -> 0 | D32: 0
A33: Chase Credit Card - United 8687 | B33: ='2024 BS'!B22 -> 4021.45 | C33: ='2025 BS'!B33 -> 49.42 | D33: 5226.16
A34: Total for Credit Cards | B34: =B31+B32+B33 -> 4021.45 | C34: =C31+C32+C33 -> 49.42 | D34: =D31+D32+D33 -> 5226.16
A35: Other Current Liabilities
A36: Commissions Due to Precision | B36: ='2024 BS'!B25 -> -45847.39 | C36: ='2025 BS'!B36 -> -281589.91 | D36: -537588.2
A37: Insurance Premiums Owed | B37: ='2024 BS'!B26 -> 175314.78 | C37: ='2025 BS'!B37 -> 788471.17 | D37: 619137.61
A38: Total for Other Current Liabilities | B38: =B35+B36+B37 -> 129467.39 | C38: =C35+C36+C37 -> 506881.26 | D38: =D35+D36+D37 -> 81549.41
A39: Total for Current Liabilities | B39: =B30+B34+B38 -> 133488.84 | C39: =C30+C34+C38 -> 506930.68 | D39: =D30+D34+D38 -> 86775.57
A40: Total for Liabilities | B40: =B29+B39 -> 133488.84 | C40: =C29+C39 -> 506930.68 | D40: =D29+D39 -> 86775.57
A41: Equity
A42: Opening balance equity | B42: ='2024 BS'!B31 -> 0 | C42: ='2025 BS'!B42 -> 0 | D42: 0
...

Sheet Trial Balance
A1: Precision Brokers, LLC
A2: Trial Balance
A3: As of Jun 30, 2026
A5: Account Name | B5: Debit | C5: Credit
A6: Chase Business Operating 2157 | B6: 117004.95
A7: Chase Premium 5805 | B7: 32739.54
A8: Operating Cash (Trust Restricted) | B8: 13293.71
A9: Operating Cash (Unrestricted) | C9: 13293.71
A10: Accounts Receivable (A/R) | B10: 25944.12
A11: Payments to deposit | C11: 0
A12: Computer and Hardware | B12: 2233.7
A13: Security deposits | B13: 9068.13
A14: Chase - Brudnicki 8695 | C14: 0
A15: Chase Credit Card - United 8687 | C15: 5226.16
A16: Commissions Due to Precision | B16: 537588.2
A17: Insurance Premiums Owed | C17: 619137.61
A18: Opening balance equity | C18: 0
A19: Partner distributions | B19: 60000
A20: Partner distributions:Hannah Brudnicki | B20: 3051.63
A21: Retained Earnings | C21: 24977.13
A22: Sales | C22: 370287.28
A23: Business licenses | B23: 1454.63
A24: Dues and Memberships | B24: 5850
A25: Employee benefits:Employee retirement plans | B25: 2300
A26: General business expenses:Bank fees & service charges | B26: 16.31
A27: General business expenses:Continuing education | B27: 5725
A28: Insurance | B28: 5995.83
A29: Legal & accounting services | B29: 97.85
A30: Legal & accounting services:Accounting fees | B30: 1875
A31: Legal & accounting services:Legal fees | B31: 2210
A32: Meals | B32: 3649.29
A33: Office expenses:Office supplies | B33: 2149.87
A34: Office expenses:Shipping & postage | B34: 2.5
... A41: Rent | B41: 5882.4
A42: Travel
A43: Travel:Airfare | B43: 8845.93
A44: Travel:Hotels | B44: 2523.87
A45: Travel:Taxis or shared rides | B45: 1068.75
A46: Vehicle expenses:Parking & tolls | B46: 175
A47: Vehicle expenses:Vehicle gas & fuel | B47: 52.15
...
